<?xml version="1.0" ?>
<!-- =================================================================================== -->
<!-- |    This document was autogenerated by xacro from src/arm12/urdf/arm12.urdf.xacro | -->
<!-- |    EDITING THIS FILE BY HAND IS NOT RECOMMENDED                                 | -->
<!-- =================================================================================== -->
<robot name="arm12">
  <!-- <robot
  name="straw"> -->
  <material name="gray">
    <color rgba="0.5 0.5 0.5 1.0"/>
  </material>
  <material name="green">
    <color rgba="0. 1 0. 1.0"/>
  </material>

  <link name="straw_base_link">
    <inertial>
      <origin rpy="0 0 0" xyz="0.72536 -2.6077 -1.278"/>
      <mass value="83.793"/>
      <inertia ixx="49.037" ixy="12.983" ixz="-0.85625" iyy="197.29" iyz="0.10604" izz="153.05"/>
    </inertial>
    <!-- <visual>
      <origin rpy="0 0 0" xyz="0 0 0"/>
      <geometry>
        <mesh filename="package://straw/meshes/straw_base_link.STL" scale="0.75 0.75 0.75"/>
      </geometry>
      <material name="gray"/>
    </visual> -->
    <collision>
      <origin rpy="0 0 0" xyz="0 0 0"/>
      <geometry>
        <mesh filename="package://straw/meshes/straw_base_link.STL"  scale="0.75 0.75 0.75"/>
      </geometry>
    </collision>
  </link>
  <link name="left_holder">
    <inertial>
      <origin rpy="0 0 0" xyz="0.068289 -1.3911 0.41242"/>
      <mass value="90.637"/>
      <inertia ixx="203.28" ixy="-5.2628E-06" ixz="-4.6215E-05" iyy="48.292" iyz="5.4272" izz="157.67"/>
    </inertial>
    <visual>
      <origin rpy="0 0 0" xyz="0 0 0"/>
      <geometry>
        <mesh filename="package://straw/meshes/left_holder.STL"  scale="0.75 0.75 0.75"/>
      </geometry>
      <material name="gray"/>
    </visual>
    <!-- <collision>
      <origin rpy="0 0 0" xyz="0 0 0"/>
      <geometry>
        <mesh filename="package://straw/meshes/left_holder.STL"  scale="0.75 0.75 0.75"/>
      </geometry>
    </collision> -->
  </link>
  <joint name="lh1" type="fixed">
    <!-- <origin rpy="-3.1003 -0.0006971 1.4841" xyz="0 0 0"/> -->
    <origin rpy="-3.1003 -0.0006971 1.4841" xyz="2.1219 -2.7952 -0.90577"/>
    <parent link="straw_base_link"/>
    <child link="left_holder"/>
    <axis xyz="0 0 0"/>
  </joint>
  <link name="pot">
    <inertial>
      <origin rpy="0 0 0" xyz="0.0723 -0.11104 1.4288"/>
      <mass value="7.0989"/>
      <inertia ixx="4.8702" ixy="1.4633E-05" ixz="-1.887E-06" iyy="4.8836" iyz="0.044366" izz="0.12976"/>
    </inertial>
    <visual>
      <origin rpy="0 0 0" xyz="0 0 0"/>
      <geometry>
        <mesh filename="package://straw/meshes/pot.STL"  scale="0.75 0.75 0.75"/>
      </geometry>
      <material name="gray"/>
    </visual>
    <collision>
      <origin rpy="0 0 0" xyz="0 0 0"/>
      <geometry>
        <mesh filename="package://straw/meshes/pot.STL"  scale="0.75 0.75 0.75"/>
      </geometry>
    </collision>
  </link>
  <joint name="lf_pot" type="fixed">
    <origin rpy="-1.5306 0 -3.1416" xyz="0.17343 0.013392 0.017884"/>
    <parent link="left_holder"/>
    <child link="pot"/>
    <axis xyz="0 0 0"/>
  </joint>
  <!-- <link name="stem1">
    <inertial>
      <origin rpy="0 0 0" xyz="0.31086 -0.35019 0.00026615"/>
      <mass value="1.1291"/>
      <inertia ixx="0.0022005" ixy="0.00034925" ixz="-8.6306E-07" iyy="0.002305" iyz="3.3465E-06" izz="0.0025724"/>
    </inertial>
    <visual>
      <origin rpy="0 0 0" xyz="0 0 0"/>
      <geometry>
        <mesh filename="package://straw/meshes/stem1.STL" scale="0.7 0.7 0.7"/>
      </geometry>
      <material name="green"/>
    </visual>
    <collision>
      <origin rpy="0 0 0" xyz="0 0 0"/>
      <geometry>
        <mesh filename="package://straw/meshes/stem1.STL" scale="0.7 0.7 0.7"/>
      </geometry>
    </collision>
  </link> -->
  <!-- <link name="straw1_intermediate">
    <inertial>
      <mass value="0.001"/>
      <inertia ixx="0.0001" ixy="0" ixz="0" iyy="0.0001" iyz="0" izz="0.0001"/>
    </inertial>
  </link> -->
  <!-- <joint name="stem1_straw1_joint_x" type="revolute">
    <parent link="stem1"/>
    <child link="straw1_intermediate"/>
    <origin rpy="0 0 0" xyz="0.33533 -0.43279 -0.0013777"/>
    <axis xyz="1 0 0"/>
    <limit effort="10" lower="-0.785" upper="0.785" velocity="1"/>
    <dynamics damping="0.5" friction="0.1"/>
  </joint> -->
  <!-- <joint name="stem1_straw1_joint_y" type="revolute">
    <parent link="straw1_intermediate"/>
    <child link="straw1"/>
    <origin rpy="0.25307 -1.4835 0" xyz="0 0 0"/>
    <axis xyz="0 1 0"/>
    <limit effort="10" lower="-0.785" upper="0.785" velocity="1"/>
    <dynamics damping="0.5" friction="0.1"/>
  </joint> -->
  <!-- <link name="straw1">
    <inertial>
      <origin rpy="0 0 0" xyz="0 0.075854 -9.8582E-07"/>
      <mass value="1.0831"/>
      <inertia ixx="0.0017742" ixy="3.2552E-19" ixz="2.1395E-23" iyy="0.0019325" iyz="3.2233E-08" izz="0.0017742"/>
    </inertial>
    <visual>
      <origin rpy="0 0 0" xyz="0 0 0"/>
      <geometry>
        <mesh filename="package://straw/meshes/straw1.STL" scale="1 1 1"/>
      </geometry>
      <material name="transparent_gray">
        <color rgba="0.5 0.5 0.5 0"/> 
      </material>
    </visual>
    <collision>
      <origin rpy="0 0 0" xyz="0 0 0"/>
      <geometry>
        <mesh filename="package://straw/meshes/straw1.STL" scale="1 1 1"/>
      </geometry>
    </collision>
  </link> -->
  <!-- <link name="stem2">
    <inertial>
      <origin rpy="0 0 0" xyz="0.32679 -0.34228 -0.0023318"/>
      <mass value="1.1291"/>
      <inertia ixx="0.0022449" ixy="0.00031251" ixz="-4.7508E-06" iyy="0.0022602" iyz="6.5609E-06" izz="0.0025727"/>
    </inertial>
    <visual>
      <origin rpy="0 0 0" xyz="0 0 0"/>
      <geometry>
        <mesh filename="package://straw/meshes/stem2.STL" scale="0.7 0.7 0.7"/>
      </geometry>
      <material name="green"/>
    </visual>
    <collision>
      <origin rpy="0 0 0" xyz="0 0 0"/>
      <geometry>
        <mesh filename="package://straw/meshes/stem2.STL" scale="0.7 0.7 0.7"/>
      </geometry>
    </collision>
  </link> -->
  <!-- <link name="straw2_intermediate">
    <inertial>
      <mass value="0.001"/>
      <inertia ixx="0.0001" ixy="0" ixz="0" iyy="0.0001" iyz="0" izz="0.0001"/>
    </inertial>
  </link> -->
  <!-- <joint name="stem2_straw2_joint_x" type="revolute">
    <parent link="stem2"/>
    <child link="straw2_intermediate"/>
    <origin rpy="0 0 0" xyz="0.37743 -0.41247 -0.0063167"/>
    <axis xyz="1 0 0"/>
    <limit effort="10" lower="-0.785" upper="0.785" velocity="1"/>
    <dynamics damping="0.5" friction="0.1"/>
  </joint> -->
  <!-- <joint name="stem2_straw2_joint_y" type="revolute">
    <parent link="straw2_intermediate"/>
    <child link="straw2"/>
    <origin rpy="0.62832 -1.4835 0" xyz="0 0 0"/>
    <axis xyz="0 1 0"/>
    <limit effort="10" lower="-0.785" upper="0.785" velocity="1"/>
    <dynamics damping="0.5" friction="0.1"/>
  </joint>
  <link name="straw2">
    <inertial>
      <origin rpy="0 0 0" xyz="0 0.075854 -9.8582E-07"/>
      <mass value="1.0831"/>
      <inertia ixx="0.0017742" ixy="2.5998E-20" ixz="2.2169E-24" iyy="0.0019325" iyz="3.2233E-08" izz="0.0017742"/>
    </inertial>
    <visual>
      <origin rpy="0 0 0" xyz="0 0 0"/>
      <geometry>
        <mesh filename="package://straw/meshes/straw2.STL" scale="1 1 1"/>
      </geometry>
      <material name="transparent_gray">
        <color rgba="0.5 0.5 0.5 0"/> 
      </material>
    </visual>
    <collision>
      <origin rpy="0 0 0" xyz="0 0 0"/>
      <geometry>
        <mesh filename="package://straw/meshes/straw2.STL" scale="1 1 1"/>
      </geometry>
    </collision>
  </link> -->
  <link name="stem3">
    <inertial>
      <origin rpy="0 0 0" xyz="0.31061 -0.35019 -0.0026474"/>
      <mass value="1.1291"/>
      <inertia ixx="0.0022005" ixy="0.00034925" ixz="-8.6306E-07" iyy="0.002305" iyz="3.3465E-06" izz="0.0025724"/>
    </inertial>
    <visual>
      <origin rpy="0 0 0" xyz="0 0 0"/>
      <geometry>
        <mesh filename="package://straw/meshes/stem3.STL" scale="0.7 0.7 0.7"/>
      </geometry>
      <!-- <material name="gray"/> -->
    </visual>
    <collision>
      <origin rpy="0 0 0" xyz="0 0 0"/>
      <geometry>
        <mesh filename="package://straw/meshes/stem3.STL" scale="0.7 0.7 0.7"/>
      </geometry>
    </collision>
  </link>
  <link name="straw3_intermediate">
    <inertial>
      <mass value="0.001"/>
      <inertia ixx="0.0001" ixy="0" ixz="0" iyy="0.0001" iyz="0" izz="0.0001"/>
    </inertial>
  </link>
  <joint name="stem3_straw3_joint_x" type="revolute">
    <parent link="stem3"/>
    <child link="straw3_intermediate"/>
    <origin rpy="0 0 0" xyz="0.33506 -0.43279 -0.0044151"/>
    <axis xyz="1 0 0"/>
    <limit effort="10" lower="-0.785" upper="0.785" velocity="1"/>
    <dynamics damping="0.5" friction="0.1"/>
  </joint>
  <joint name="stem3_straw3_joint_y" type="revolute">
    <parent link="straw3_intermediate"/>
    <child link="straw3"/>
    <origin rpy="0.25307 -1.4835 0" xyz="0 0 0"/>
    <axis xyz="0 1 0"/>
    <limit effort="10" lower="-0.785" upper="0.785" velocity="1"/>
    <dynamics damping="0.5" friction="0.1"/>
  </joint>
  <link name="straw3">
    <inertial>
      <origin rpy="0 0 0" xyz="-2.2204E-16 0.075854 -9.8582E-07"/>
      <mass value="1.0831"/>
      <inertia ixx="0.0017742" ixy="6.2414E-20" ixz="1.0659E-23" iyy="0.0019325" iyz="3.2233E-08" izz="0.0017742"/>
    </inertial>
    <visual>
      <origin rpy="0 0 0" xyz="0 0 0"/>
      <geometry>
        <mesh filename="package://straw/meshes/straw3.STL" scale="1 1 1" />
      </geometry>
      <material name="transparent_gray">
        <color rgba="0.5 0.5 0.5 0"/> 
      </material>

    </visual>
    <!-- <collision>
      <origin rpy="0 0 0" xyz="0 0 0"/>
      <geometry>
        <mesh filename="package://straw/meshes/straw3.STL" scale="0.75 0.75 0.75"/>
      </geometry>
    </collision> -->
  </link>
  <!-- <link name="right_holder">
    <inertial>
      <origin rpy="0 0 0" xyz="0.16998 1.3378 0.16679"/>
      <mass value="7.0141"/>
      <inertia ixx="4.8686" ixy="1.7169E-06" ixz="-4.633E-05" iyy="0.12782" iyz="-0.073617" izz="4.8819"/>
    </inertial>
    <visual>
      <origin rpy="0 0 0" xyz="0 0 0"/>
      <geometry>
        <mesh filename="package://straw/meshes/right_holder.STL"/>
      </geometry>
      <material name="gray"/>
    </visual>
    <collision>
      <origin rpy="0 0 0" xyz="0 0 0"/>
      <geometry>
        <mesh filename="package://straw/meshes/right_holder.STL"/>
      </geometry>
    </collision>
  </link> -->
  <!-- <joint name="rh1" type="fixed">
    <origin rpy="3.1178 -0.0006971 1.4841" xyz="-0.64819 -2.6236 -0.90294"/>
    <parent link="base_link"/>
    <child link="right_holder"/>
    <axis xyz="0 0 0"/>
  </joint> -->
  <link name="stem1_intermediate1">
    <inertial>
      <mass value="0.001"/>
      <inertia ixx="0.0001" ixy="0" ixz="0" iyy="0.0001" iyz="0" izz="0.0001"/>
    </inertial>
  </link>
  <link name="stem1_intermediate2">
    <inertial>
      <mass value="0.001"/>
      <inertia ixx="0.0001" ixy="0" ixz="0" iyy="0.0001" iyz="0" izz="0.0001"/>
    </inertial>
  </link>
  <joint name="pot_stem1_x" type="revolute">
    <parent link="pot"/>
    <child link="stem1_intermediate1"/>
    <origin rpy="0 0 0" xyz="-0.069846 0.034051 0.92078"/>
    <axis xyz="1 0 0"/>
    <limit effort="10" lower="-0.523" upper="0.523" velocity="1"/>
    <dynamics damping="0.5" friction="0.1"/>
  </joint>
  <joint name="pot_stem1_y" type="revolute">
    <parent link="stem1_intermediate1"/>
    <child link="stem1_intermediate2"/>
    <origin rpy="0 0 0" xyz="0 0 0"/>
    <axis xyz="0 1 0"/>
    <limit effort="10" lower="-0.523" upper="0.523" velocity="1"/>
    <dynamics damping="0.5" friction="0.1"/>
  </joint>
  <!-- <joint name="pot_stem1_z" type="revolute">
    <parent link="stem1_intermediate2"/>
    <child link="stem1"/>
    <origin rpy="3.1189 0.0035789 -2.8888" xyz="0 0 0"/>
    <axis xyz="0 0 1"/>
    <limit effort="10" lower="-0.523" upper="0.523" velocity="1"/>
    <dynamics damping="0.5" friction="0.1"/>
  </joint> -->
  <link name="stem2_intermediate1">
    <inertial>
      <mass value="0.001"/>
      <inertia ixx="0.0001" ixy="0" ixz="0" iyy="0.0001" iyz="0" izz="0.0001"/>
    </inertial>
  </link>
  <link name="stem2_intermediate2">
    <inertial>
      <mass value="0.001"/>
      <inertia ixx="0.0001" ixy="0" ixz="0" iyy="0.0001" iyz="0" izz="0.0001"/>
    </inertial>
  </link>
  <joint name="pot_stem2_x" type="revolute">
    <parent link="pot"/>
    <child link="stem2_intermediate1"/>
    <origin rpy="0 0 0" xyz="-0.071011 0.062145 0.99538"/>
    <axis xyz="1 0 0"/>
    <limit effort="10" lower="-0.523" upper="0.523" velocity="1"/>
    <dynamics damping="0.5" friction="0.1"/>
  </joint>
  <joint name="pot_stem2_y" type="revolute">
    <parent link="stem2_intermediate1"/>
    <child link="stem2_intermediate2"/>
    <origin rpy="0 0 0" xyz="0 0 0"/>
    <axis xyz="0 1 0"/>
    <limit effort="10" lower="-0.523" upper="0.523" velocity="1"/>
    <dynamics damping="0.5" friction="0.1"/>
  </joint>
  <!-- <joint name="pot_stem2_z" type="revolute">
    <parent link="stem2_intermediate2"/>
    <child link="stem2"/>
    <origin rpy="3.0898 0.017653 -2.5152" xyz="0 0 0"/>
    <axis xyz="0 0 1"/>
    <limit effort="10" lower="-0.523" upper="0.523" velocity="1"/>
    <dynamics damping="0.5" friction="0.1"/>
  </joint> -->
  <link name="stem3_intermediate1">
    <inertial>
      <mass value="0.001"/>
      <inertia ixx="0.0001" ixy="0" ixz="0" iyy="0.0001" iyz="0" izz="0.0001"/>
    </inertial>
  </link>
  <link name="stem3_intermediate2">
    <inertial>
      <mass value="0.001"/>
      <inertia ixx="0.0001" ixy="0" ixz="0" iyy="0.0001" iyz="0" izz="0.0001"/>
    </inertial>
  </link>
  <joint name="pot_stem3_x" type="revolute">
    <parent link="pot"/>
    <child link="stem3_intermediate1"/>
    <origin rpy="0 0 0" xyz="-0.05556 0.033891 1.0852"/>
    <axis xyz="1 0 0"/>
    <limit effort="10" lower="-0.523" upper="0.523" velocity="1"/>
    <dynamics damping="0.5" friction="0.1"/>
  </joint>
  <joint name="pot_stem3_y" type="revolute">
    <parent link="stem3_intermediate1"/>
    <child link="stem3_intermediate2"/>
    <origin rpy="0 0 0" xyz="0 0 0"/>
    <axis xyz="0 1 0"/>
    <limit effort="10" lower="-0.523" upper="0.523" velocity="1"/>
    <dynamics damping="0.5" friction="0.1"/>
  </joint>
  <joint name="pot_stem3_z" type="revolute">
    <parent link="stem3_intermediate2"/>
    <child link="stem3"/>
    <origin rpy="3.1189 0.0035789 -2.8888" xyz="0 0 0"/>
    <axis xyz="0 0 1"/>
    <limit effort="10" lower="-0.523" upper="0.523" velocity="1"/>
    <dynamics damping="0.5" friction="0.1"/>
  </joint>
  <link name="rotated_base"/>
  <joint name="rot_to_base" type="fixed">
    <parent link="rotated_base"/>
    <child link="base_link"/>
    <origin rpy="0 3.14 0" xyz="0 0 0"/>
  </joint>
  <joint name="attach_straw" type="fixed">
    <parent link="rotated_base"/>
    <child link="straw_base_link"/>
    <origin rpy="0 0 0.1" xyz="-1.3 2.3 2"/>
  </joint>
  <link name="base_link">
    <inertial>
      <origin rpy="0 0 0" xyz="-0.114741653388133 -0.00394836028883594 -0.0536105920933669"/>
      <mass value="2.63443753992699"/>
      <inertia ixx="0.00189567328668365" ixy="7.29873865389891E-06" ixz="0.000140090900098037" iyy="0.158992383742472" iyz="1.36209227842431E-06" izz="0.158257846821755"/>
    </inertial>
    <visual>
      <origin rpy="0 0 0" xyz="0 0 0"/>
      <geometry>
        <mesh filename="package://arm12/meshes/base_link.STL"/>
      </geometry>
      <material name="">
        <color rgba="0.792156862745098 0.819607843137255 0.933333333333333 1"/>
      </material>
    </visual>
    <collision>
      <origin rpy="0 0 0" xyz="0 0 0"/>
      <geometry>
        <mesh filename="package://arm12/meshes/base_link.STL"/>
      </geometry>
    </collision>
  </link>
  <link name="l1">
    <inertial>
      <origin rpy="0 0 0" xyz="0.403597483420043 -0.0414638574022828 0.00700359932104074"/>
      <mass value="0.381600228345592"/>
      <inertia ixx="0.000152419359459052" ixy="-1.16717541525886E-07" ixz="-4.78639401455686E-07" iyy="0.00015874224871389" iyz="3.26007402233397E-07" izz="0.000167838112577603"/>
    </inertial>
    <visual>
      <origin rpy="0 0 0" xyz="0 0 0"/>
      <geometry>
        <mesh filename="package://arm12/meshes/l1.STL"/>
      </geometry>
      <material name="">
        <color rgba="0.898039215686275 0.917647058823529 0.929411764705882 1"/>
      </material>
    </visual>
    <collision>
      <origin rpy="0 0 0" xyz="0 0 0"/>
      <geometry>
        <mesh filename="package://arm12/meshes/l1.STL"/>
      </geometry>
    </collision>
  </link>
  <joint name="j1" type="prismatic">
    <origin rpy="1.5708 0 0" xyz="-0.79073 0.0075 -0.026676"/>
    <parent link="base_link"/>
    <child link="l1"/>
    <axis xyz="1 0.00024256 0"/>
    <limit effort="1000" lower="-0.37" upper="0.35" velocity="1000"/>
  </joint>
  <link name="l11">
    <inertial>
      <origin rpy="0 0 0" xyz="0.109124708134365 -0.106742142823085 0.0291269836365173"/>
      <mass value="0.308192429361636"/>
      <inertia ixx="0.00036660835632017" ixy="0.000236532188858594" ixz="-5.91891737788076E-05" iyy="0.000377052003364126" iyz="5.79126892712075E-05" izz="0.000595833629485193"/>
    </inertial>
    <visual>
      <origin rpy="0 0 0" xyz="0 0 0"/>
      <geometry>
        <mesh filename="package://arm12/meshes/l11.STL"/>
      </geometry>
      <material name="">
        <color rgba="0.792156862745098 0.819607843137255 0.933333333333333 1"/>
      </material>
    </visual>
    <collision>
      <origin rpy="0 0 0" xyz="0 0 0"/>
      <geometry>
        <mesh filename="package://arm12/meshes/l11.STL"/>
      </geometry>
    </collision>
  </link>
  <joint name="j11" type="continuous">
    <origin rpy="0 0 0" xyz="0.403574468337888 -0.0486058728976355 -0.000248553231492891"/>
    <parent link="l1"/>
    <child link="l11"/>
    <axis xyz="0 0 -1"/>
  </joint>
  <link name="l2">
    <inertial>
      <origin rpy="0 0 0" xyz="1.0157003601035 -0.0384463563381593 0.00765610841163893"/>
      <mass value="0.51688405008029"/>
      <inertia ixx="0.000289252991255811" ixy="6.16500231917276E-07" ixz="-1.38368241480024E-06" iyy="0.000291829291446418" iyz="-1.10552388292668E-06" izz="0.00026788505040365"/>
    </inertial>
    <visual>
      <origin rpy="0 0 0" xyz="0 0 0"/>
      <geometry>
        <mesh filename="package://arm12/meshes/l2.STL"/>
      </geometry>
      <material name="">
        <color rgba="0.898039215686275 0.917647058823529 0.929411764705882 1"/>
      </material>
    </visual>
    <collision>
      <origin rpy="0 0 0" xyz="0 0 0"/>
      <geometry>
        <mesh filename="package://arm12/meshes/l2.STL"/>
      </geometry>
    </collision>
  </link>
  <joint name="j2" type="prismatic">
    <origin rpy="1.5708 0 0" xyz="-0.79073 0.0075 -0.026676"/>
    <parent link="base_link"/>
    <child link="l2"/>
    <axis xyz="1 0.00024256 0"/>
    <limit effort="1000" lower="-0.26" upper="0.32" velocity="1000"/>
  </joint>
  <link name="l3">
    <inertial>
      <origin rpy="0 0 0" xyz="-0.10814121670337 -0.105773126393835 0.0288760940795127"/>
      <mass value="0.306128922940993"/>
      <inertia ixx="0.000367090541907876" ixy="-0.000237220677320172" ixz="5.90721357269542E-05" iyy="0.000377593275938236" iyz="5.77716342409563E-05" izz="0.000596928132744383"/>
    </inertial>
    <visual>
      <origin rpy="0 0 0" xyz="0 0 0"/>
      <geometry>
        <mesh filename="package://arm12/meshes/l3.STL"/>
      </geometry>
      <material name="">
        <color rgba="0.792156862745098 0.819607843137255 0.933333333333333 1"/>
      </material>
    </visual>
    <collision>
      <origin rpy="0 0 0" xyz="0 0 0"/>
      <geometry>
        <mesh filename="package://arm12/meshes/l3.STL"/>
      </geometry>
    </collision>
  </link>
  <joint name="j3" type="revolute">
    <origin rpy="0 0 0" xyz="1.0158 -0.048606 -0.00024711"/>
    <parent link="l2"/>
    <child link="l3"/>
    <axis xyz="0 0 -1"/>
    <limit effort="1000" lower="-0.65" upper="0.7" velocity="1000"/>
  </joint>
  <link name="l4">
    <inertial>
      <origin rpy="0 0 0" xyz="-0.0247644704780808 -0.0233597492007901 0.033905617015353"/>
      <mass value="0.247877954974344"/>
      <inertia ixx="0.000275512262276771" ixy="-4.01235172214852E-08" ixz="5.68470398676511E-07" iyy="0.000303231827207215" iyz="4.68448608364464E-05" izz="0.000495903390975614"/>
    </inertial>
    <visual>
      <origin rpy="0 0 0" xyz="0 0 0"/>
      <geometry>
        <mesh filename="package://arm12/meshes/l4.STL"/>
      </geometry>
      <material name="">
        <color rgba="1 1 1 1"/>
      </material>
    </visual>
    <collision>
      <origin rpy="0 0 0" xyz="0 0 0"/>
      <geometry>
        <mesh filename="package://arm12/meshes/l4.STL"/>
      </geometry>
    </collision>
  </link>
  <joint name="j4" type="continuous">
    <origin rpy="0 0 0" xyz="-0.2814 -0.27508 0.049459"/>
    <parent link="l3"/>
    <child link="l4"/>
    <axis xyz="0 0 1"/>
    <limit effort="1000" lower="1000" upper="1000" velocity="1000"/>
    <mimic joint="j3" multiplier="1" offset="0"/>
  </joint>
  <link name="l6">
    <inertial>
      <origin rpy="0 0 0" xyz="0.0835083121801821 -0.0131318490598266 -0.022315022598535"/>
      <mass value="0.492993890644909"/>
      <inertia ixx="0.000390471608455916" ixy="2.48268434817755E-06" ixz="0.000302295718302552" iyy="0.00155512945705818" iyz="-1.20122073303538E-06" izz="0.00147705952278512"/>
    </inertial>
    <visual>
      <origin rpy="0 0 0" xyz="0 0 0"/>
      <geometry>
        <mesh filename="package://arm12/meshes/l6.STL"/>
      </geometry>
      <material name="">
        <color rgba="1 1 1 1"/>
      </material>
    </visual>
    <collision>
      <origin rpy="0 0 0" xyz="0 0 0"/>
      <geometry>
        <mesh filename="package://arm12/meshes/l6.STL"/>
      </geometry>
    </collision>
  </link>
  <joint name="j6" type="continuous">
    <origin rpy="0 0 0" xyz="-0.031134 -0.097956 0.059414"/>
    <parent link="l4"/>
    <child link="l6"/>
    <axis xyz="0 1 0"/>
    <limit effort="1000" lower="1000" upper="1000" velocity="1000"/>
  </joint>
  <link name="l7">
    <inertial>
      <origin rpy="0 0 0" xyz="0.0315318501806746 0.00583507478957768 -0.0817967507514115"/>
      <mass value="0.200740625287396"/>
      <inertia ixx="0.000563180696639149" ixy="8.48547014814516E-05" ixz="0.000202999903698582" iyy="0.000610313185565538" iyz="-0.000156946216691284" izz="0.000315973335029523"/>
    </inertial>
    <visual>
      <origin rpy="0 0 0" xyz="0 0 0"/>
      <geometry>
        <mesh filename="package://arm12/meshes/l7.STL"/>
      </geometry>
      <material name="">
        <color rgba="0.792156862745098 0.819607843137255 0.933333333333333 1"/>
      </material>
    </visual>
    <collision>
      <origin rpy="0 0 0" xyz="0 0 0"/>
      <geometry>
        <mesh filename="package://arm12/meshes/l7.STL"/>
      </geometry>
    </collision>
  </link>
  <joint name="j7" type="continuous">
    <origin rpy="0 0 0" xyz="0.16802 0 -0.043732"/>
    <parent link="l6"/>
    <child link="l7"/>
    <axis xyz="0 1 0"/>
    <limit effort="1000" lower="1000" upper="1000" velocity="1000"/>
  </joint>
  <link name="l8">
    <inertial>
      <origin rpy="0 0 0" xyz="-0.00639785855543679 -0.105467190035519 0.0332454721635889"/>
      <mass value="0.232745208884819"/>
      <inertia ixx="0.000344329566709667" ixy="-0.000100351533357395" ixz="-3.41790292256826E-06" iyy="0.000220748774570507" iyz="9.99580236012298E-06" izz="0.000406188026813068"/>
    </inertial>
    <visual>
      <origin rpy="0 1.57 0" xyz="-0.042  -0.274 0.085"/>
      <geometry>
        <mesh filename="package://arm12/meshes/l8.STL"/>
      </geometry>
      <material name="">
        <color rgba="0.898039215686275 0.917647058823529 0.929411764705882 1"/>
      </material>
    </visual>
    <collision>
      <origin rpy="0 1.57 0" xyz="-0.042  -0.274 0.085"/>
      <geometry>
        <mesh filename="package://arm12/meshes/l8.STL"/>
      </geometry>
    </collision>
  </link>
  <joint name="j8" type="continuous">
    <origin rpy="0.48 -0.47 0" xyz="0.057439 -0.0094087 -0.13"/>
    <parent link="l7"/>
    <child link="l8"/>
    <axis xyz="-1 0 0"/>
    <limit effort="1000" lower="1000" upper="1000" velocity="1000"/>
  </joint>
  <link name="tool0">
    <inertial>
      <origin rpy="0 0 0" xyz="0.0835083121801821 -0.0131318490598266 -0.022315022598535"/>
      <mass value="0.492993890644909"/>
      <inertia ixx="0.000390471608455916" ixy="2.48268434817755E-06" ixz="0.000302295718302552" iyy="0.00155512945705818" iyz="-1.20122073303538E-06" izz="0.00147705952278512"/>
    </inertial>
    <visual>
      <origin rpy="1.57 0 0" xyz="-0.0773 0.042 -0.036"/>
      <geometry>
        <mesh filename="package://arm12/meshes/gripper.STL"/>
      </geometry>
      <material name="">
        <color rgba="0.792156862745098 0.819607843137255 0.933333333333333 1"/>
      </material>
    </visual>
    <collision>
      <origin rpy="0 0 0 " xyz="0 0 0"/>
      <geometry>
        <mesh filename="package://arm12/meshes/gripper.STL"/>
      </geometry>
    </collision>
  </link>
  <joint name="tool0_joint" type="continuous">
    <axis xyz="0 -1 0"/>
    <limit effort="1000" lower="1000" upper="1000" velocity="1000"/>
    <parent link="l8"/>
    <child link="tool0"/>
    <origin rpy="-0.48 0 0" xyz="-0.007 -0.09 0.047"/>
  </joint>
</robot>
<!-- <origin xyz="-0.025 -0.2 0.05" rpy="-0.35 -0.50 0"/> -->

