<?xml version="1.0" encoding="utf-8" ?>
<robot name="double_arm">
    <link name="scout_base_link">
        <visual>
            <origin xyz="0 0 0" rpy="1.5707 0 -1.5707" />
            <geometry>
                <mesh filename="package://piper_description/meshes/scout_mini_base_link.dae" />
            </geometry>
        </visual>
        <collision>
            <origin xyz="0 0 0" rpy="1.5707 0 -1.5707" />
            <geometry>
                <mesh filename="package://piper_description/meshes/scout_mini_base_link.dae" />
            </geometry>
        </collision>
        <inertial>
            <mass value="0.1" />
            <origin xyz="0 0 0" rpy="0 0 0" />
            <inertia ixx="0.03" iyy="0.03" izz="0.03" ixy="0.0" ixz="0.0" iyz="0.0" />
        </inertial>
    </link>
    <link name="inertial_link">
        <inertial>
            <mass value="60" />
            <origin xyz="0.0 0.0 0.0" />
            <inertia ixx="2.288641" ixy="0" ixz="0" iyy="5.103976" iyz="0" izz="3.431465" />
        </inertial>
    </link>
    <joint name="inertial_joint" type="fixed">
        <origin xyz="0 0 0" rpy="0 0 0" />
        <parent link="scout_base_link" />
        <child link="inertial_link" />
    </joint>
    <!-- 定义前右轮 -->
    <link name="wheel_front_right">
        <visual>
            <origin xyz="0 0 0" rpy="0 0 0" />
            <geometry>
                <mesh filename="package://piper_description/meshes/1_Link.STL" scale="1 1 1" />
            </geometry>
            <material name="black">
                <color rgba="0 0 0 1" />
            </material>
        </visual>
        <collision>
            <origin xyz="0 0 0" rpy="0 0 0" />
            <geometry>
                <mesh filename="package://piper_description/meshes/1_Link.STL" scale="1 1 1" />
            </geometry>
        </collision>
        <inertial>
            <origin xyz="0 0 0" rpy="0 0 0" />
            <mass value="2" />
            <inertia ixx="0.01" iyy="0.01" izz="0.01" ixy="0" ixz="0" iyz="0" />
        </inertial>
    </link>
    <joint name="joint_wheel_front_right" type="continuous">
        <parent link="scout_base_link" />
        <child link="wheel_front_right" />
        <origin xyz="0.2319775 -0.16825 -0.100998" rpy="1.57 0 0" />
        <axis xyz="0 0 -1" />
    </joint>
    <!-- 定义前左轮 -->
    <link name="wheel_front_left">
        <visual>
            <origin xyz="0 0 0" rpy="0 0 0" />
            <geometry>
                <mesh filename="package://piper_description/meshes/2_Link.STL" scale="1 1 1" />
            </geometry>
            <material name="black" />
        </visual>
        <collision>
            <origin xyz="0 0 0" rpy="0 0 0" />
            <geometry>
                <mesh filename="package://piper_description/meshes/2_Link.STL" scale="1 1 1" />
            </geometry>
        </collision>
        <inertial>
            <origin xyz="0 0 0" rpy="0 0 0" />
            <mass value="2" />
            <inertia ixx="0.01" iyy="0.01" izz="0.01" ixy="0" ixz="0" iyz="0" />
        </inertial>
    </link>
    <joint name="joint_wheel_front_left" type="continuous">
        <parent link="scout_base_link" />
        <child link="wheel_front_left" />
        <!-- 位置：x = wheelbase/2, y = track/2, z = wheel_vertical_offset -->
        <origin xyz="0.2319775 0.16825 -0.100998" rpy="-1.57 0 0" />
        <axis xyz="0 0 1" />
    </joint>
    <!-- 定义后左轮 -->
    <link name="wheel_rear_left">
        <visual>
            <origin xyz="0 0 0" rpy="0 0 0" />
            <geometry>
                <mesh filename="package://piper_description/meshes/3_Link.STL" scale="1 1 1" />
            </geometry>
            <material name="black" />
        </visual>
        <collision>
            <origin xyz="0 0 0" rpy="0 0 0" />
            <geometry>
                <mesh filename="package://piper_description/meshes/3_Link.STL" scale="1 1 1" />
            </geometry>
        </collision>
        <inertial>
            <origin xyz="0 0 0" rpy="0 0 0" />
            <mass value="2" />
            <inertia ixx="0.01" iyy="0.01" izz="0.01" ixy="0" ixz="0" iyz="0" />
        </inertial>
    </link>
    <joint name="joint_wheel_rear_left" type="continuous">
        <parent link="scout_base_link" />
        <child link="wheel_rear_left" />
        <!-- 位置：x = -wheelbase/2, y = track/2, z = wheel_vertical_offset -->
        <origin xyz="-0.2319775 0.16825 -0.100998" rpy="-1.57 0 0" />
        <axis xyz="0 0 1" />
    </joint>
    <!-- 定义后右轮 -->
    <link name="wheel_rear_right">
        <visual>
            <origin xyz="0 0 0" rpy="0 0 0" />
            <geometry>
                <mesh filename="package://piper_description/meshes/4_Link.STL" scale="1 1 1" />
            </geometry>
            <material name="black" />
        </visual>
        <collision>
            <origin xyz="0 0 0" rpy="0 0 0" />
            <geometry>
                <mesh filename="package://piper_description/meshes/4_Link.STL" scale="1 1 1" />
            </geometry>
        </collision>
        <inertial>
            <origin xyz="0 0 0" rpy="0 0 0" />
            <mass value="2" />
            <inertia ixx="0.01" iyy="0.01" izz="0.01" ixy="0" ixz="0" iyz="0" />
        </inertial>
    </link>
    <joint name="joint_wheel_rear_right" type="continuous">
        <parent link="scout_base_link" />
        <child link="wheel_rear_right" />
        <!-- 位置：x = -wheelbase/2, y = -track/2, z = wheel_vertical_offset -->
        <origin xyz="-0.2319775 -0.16825 -0.100998" rpy="1.57 0 0" />
        <axis xyz="0 0 -1" />
    </joint>
    <!-- 上部结构（upper_double） -->
    <link name="double_arm_upper">
        <visual>
            <origin xyz="-0.15 -0.315 -0.03" rpy="1.5707 0 1.5707" />
            <geometry>
                <mesh filename="package://piper_description/meshes/upper_double.STL" scale="1 1 1" />
            </geometry>
            <material name="aluminum">
                <color rgba="0.8 0.8 0.8 1.0" />
            </material>
        </visual>
        <collision>
            <origin xyz="-0.15 -0.315 -0.03" rpy="1.5707 0 1.5707" />
            <geometry>
                <mesh filename="package://piper_description/meshes/upper_double.STL" scale="1 1 1" />
            </geometry>
        </collision>
        <inertial>
            <origin xyz="0 0 0" rpy="0 0 0" />
            <mass value="2" />
            <inertia ixx="0.01" iyy="0.01" izz="0.01" ixy="0" ixz="0" iyz="0" />
        </inertial>
    </link>
    <joint name="upper_to_base" type="fixed">
        <parent link="scout_base_link" />
        <child link="double_arm_upper" />
        <origin xyz="0 0 0" rpy="0 0 0" />
    </joint>
    <!-- piper left -->
    <link name="piper_base_link_left">
        <inertial>
            <origin xyz="-0.00473641164191482 2.56829134630247E-05 0.041451518036016" rpy="0 0 0" />
            <mass value="1.02" />
            <inertia ixx="0.00267433" ixy="-0.00000073" ixz="-0.00017389" iyy="0.00282612" iyz="0.0000004" izz="0.00089624" />
        </inertial>
        <visual>
            <origin xyz="0 0 0" rpy="0 0 0" />
            <geometry>
                <mesh filename="package://piper_description/meshes/piper_base_link.STL" />
            </geometry>
            <material name="">
                <color rgba="0.792156862745098 0.819607843137255 0.933333333333333 1" />
            </material>
        </visual>
        <collision>
            <origin xyz="0 0 0" rpy="0 0 0" />
            <geometry>
                <mesh filename="package://piper_description/meshes/piper_base_link.STL" />
            </geometry>
        </collision>
    </link>
    <joint name="left_piper_fix" type="fixed">
        <parent link="double_arm_upper" />
        <child link="piper_base_link_left" />
        <origin xyz="0.053 0.255 0.57" rpy="0 0 0" />
    </joint>
    <link name="left_link1">
        <inertial>
            <origin xyz="0.000121504734057468 0.000104632162460536 -0.00438597309559853" rpy="0 0 0" />
            <mass value="0.71" />
            <inertia ixx="0.00048916" ixy="-0.00000036" ixz="-0.00000224" iyy="0.00040472" iyz="-0.00000242" izz="0.00043982" />
        </inertial>
        <visual>
            <origin xyz="0 0 0" rpy="0 0 0" />
            <geometry>
                <mesh filename="package://piper_description/meshes/piper_link1.STL" />
            </geometry>
            <material name="">
                <color rgba="0.792156862745098 0.819607843137255 0.933333333333333 1" />
            </material>
        </visual>
        <collision>
            <origin xyz="0 0 0" rpy="0 0 0" />
            <geometry>
                <mesh filename="package://piper_description/meshes/piper_link1.STL" />
            </geometry>
        </collision>
    </link>
    <joint name="left_joint1" type="revolute">
        <origin xyz="0 0 0.123" rpy="0 0 0" />
        <parent link="piper_base_link_left" />
        <child link="left_link1" />
        <axis xyz="0 0 1" />
        <limit lower="-2.618" upper="2.168" effort="100" velocity="5" />
    </joint>
    <link name="left_link2">
        <inertial>
            <origin xyz="0.198666145229743 -0.010926924140076 0.00142121714502687" rpy="0 0 0" />
            <mass value="1.17" />
            <inertia ixx="0.00116918" ixy="-0.00180037" ixz="0.00025146" iyy="0.06785384" iyz="-0.00000455" izz="0.06774489" />
        </inertial>
        <visual>
            <origin xyz="0 0 0" rpy="0 0 0" />
            <geometry>
                <mesh filename="package://piper_description/meshes/piper_link2.STL" />
            </geometry>
            <material name="">
                <color rgba="0.792156862745098 0.819607843137255 0.933333333333333 1" />
            </material>
        </visual>
        <collision>
            <origin xyz="0 0 0" rpy="0 0 0" />
            <geometry>
                <mesh filename="package://piper_description/meshes/piper_link2.STL" />
            </geometry>
        </collision>
    </link>
    <joint name="left_joint2" type="revolute">
        <origin xyz="0 0 0" rpy="1.5708 -0.10095 -3.1416" />
        <parent link="left_link1" />
        <child link="left_link2" />
        <axis xyz="0 0 1" />
        <limit lower="0" upper="3.14" effort="100" velocity="5" />
    </joint>
    <link name="left_link3">
        <inertial>
            <origin xyz="-0.0202737662122021 -0.133914995944595 -0.000458682652737356" rpy="0 0 0" />
            <mass value="0.5" />
            <inertia ixx="0.01361711" ixy="0.00165794" ixz="-0.00000048" iyy="0.00045024" iyz="-0.00000045" izz="0.01380322" />
        </inertial>
        <visual>
            <origin xyz="0 0 0" rpy="0 0 0" />
            <geometry>
                <mesh filename="package://piper_description/meshes/piper_link3.STL" />
            </geometry>
            <material name="">
                <color rgba="0.792156862745098 0.819607843137255 0.933333333333333 1" />
            </material>
        </visual>
        <collision>
            <origin xyz="0 0 0" rpy="0 0 0" />
            <geometry>
                <mesh filename="package://piper_description/meshes/piper_link3.STL" />
            </geometry>
        </collision>
    </link>
    <joint name="left_joint3" type="revolute">
        <origin xyz="0.28503 0 0" rpy="0 0 -1.759" />
        <parent link="left_link2" />
        <child link="left_link3" />
        <axis xyz="0 0 1" />
        <limit lower="-2.967" upper="0" effort="100" velocity="5" />
    </joint>
    <link name="left_link4">
        <inertial>
            <origin xyz="-9.66635791618542E-05 0.000876064475651083 -0.00496880904640868" rpy="0 0 0" />
            <mass value="0.38" />
            <inertia ixx="0.00018501" ixy="0.00000054" ixz="0.00000120" iyy="0.00018965" iyz="-0.00000841" izz="0.00015484" />
        </inertial>
        <visual>
            <origin xyz="0 0 0" rpy="0 0 0" />
            <geometry>
                <mesh filename="package://piper_description/meshes/piper_link4.STL" />
            </geometry>
            <material name="">
                <color rgba="0.792156862745098 0.819607843137255 0.933333333333333 1" />
            </material>
        </visual>
        <collision>
            <origin xyz="0 0 0" rpy="0 0 0" />
            <geometry>
                <mesh filename="package://piper_description/meshes/piper_link4.STL" />
            </geometry>
        </collision>
    </link>
    <joint name="left_joint4" type="revolute">
        <origin xyz="-0.021984 -0.25075 0" rpy="1.5708 0 0" />
        <parent link="left_link3" />
        <child link="left_link4" />
        <axis xyz="0 0 1" />
        <limit lower="-1.745" upper="1.745" effort="100" velocity="5" />
    </joint>
    <link name="left_link5">
        <inertial>
            <origin xyz="-4.10554118924211E-05 -0.0566486692356075 -0.0037205791677906" rpy="0 0 0" />
            <mass value="0.383" />
            <inertia ixx="0.00166169" ixy="0.00000006" ixz="-0.00000007" iyy="0.00018510" iyz="0.00001026" izz="0.00164321" />
        </inertial>
        <visual>
            <origin xyz="0 0 0" rpy="0 0 0" />
            <geometry>
                <mesh filename="package://piper_description/meshes/piper_link5.STL" />
            </geometry>
            <material name="">
                <color rgba="0.792156862745098 0.819607843137255 0.933333333333333 1" />
            </material>
        </visual>
        <collision>
            <origin xyz="0 0 0" rpy="0 0 0" />
            <geometry>
                <mesh filename="package://piper_description/meshes/piper_link5.STL" />
            </geometry>
        </collision>
    </link>
    <joint name="left_joint5" type="revolute">
        <origin xyz="0 0 0" rpy="-1.5708 0 0" />
        <parent link="left_link4" />
        <child link="left_link5" />
        <axis xyz="0 0 1" />
        <limit lower="-1.22" upper="1.22" effort="100" velocity="5" />
    </joint>
    <link name="left_link6">
        <inertial>
            <origin xyz="-8.82590762930069E-05 9.0598378529832E-06 -0.002" rpy="0 0 0" />
            <mass value="0.00699089613564366" />
            <inertia ixx="5.73015540542155E-07" ixy="-1.98305403089247E-22" ixz="-7.2791893904596E-23" iyy="5.73015540542155E-07" iyz="-3.4146026640245E-24" izz="1.06738869138926E-06" />
        </inertial>
        <visual>
            <origin xyz="0 0 0" rpy="0 0 0" />
            <geometry>
                <mesh filename="package://piper_description/meshes/piper_link6.STL" />
            </geometry>
            <material name="">
                <color rgba="0.898039215686275 0.917647058823529 0.929411764705882 1" />
            </material>
        </visual>
        <collision>
            <origin xyz="0 0 0" rpy="0 0 0" />
            <geometry>
                <mesh filename="package://piper_description/meshes/piper_link6.STL" />
            </geometry>
        </collision>
    </link>
    <joint name="left_joint6" type="revolute">
        <origin xyz="8.8259E-05 -0.091 0" rpy="1.5708 0 0" />
        <parent link="left_link5" />
        <child link="left_link6" />
        <axis xyz="0 0 1" />
        <limit lower="-2.0944" upper="2.0944" effort="100" velocity="3" />
    </joint>
    <link name="left_gripper_base">
        <inertial>
            <origin xyz="-0.000183807162235591 8.05033155577911E-05 0.0321436689908876" rpy="0 0 0" />
            <mass value="0.45" />
            <inertia ixx="0.00092934" ixy="0.00000034" ixz="-0.00000738" iyy="0.00071447" iyz="0.00000005" izz="0.00039442" />
        </inertial>
        <visual>
            <origin xyz="0 0 0" rpy="0 0 0" />
            <geometry>
                <mesh filename="package://piper_description/meshes/gripper_base.STL" />
            </geometry>
            <material name="">
                <color rgba="0.792156862745098 0.819607843137255 0.933333333333333 1" />
            </material>
        </visual>
        <collision>
            <origin xyz="0 0 0" rpy="0 0 0" />
            <geometry>
                <mesh filename="package://piper_description/meshes/gripper_base.STL" />
            </geometry>
        </collision>
    </link>
    <joint name="left_joint6_to_gripper_base" type="fixed">
        <origin xyz="0 0 0" rpy="0 0 0" />
        <parent link="left_link6" />
        <child link="left_gripper_base" />
    </joint>
    <link name="left_link7">
        <inertial>
            <origin xyz="0.00065123185041968 -0.0491929869131989 0.00972258769184025" rpy="0 0 0" />
            <mass value="0.025" />
            <inertia ixx="0.00007371" ixy="-0.00000113" ixz="0.00000021" iyy="0.00000781" iyz="-0.00001372" izz="0.0000747" />
        </inertial>
        <visual>
            <origin xyz="0 0 0" rpy="0 0 0" />
            <geometry>
                <mesh filename="package://piper_description/meshes/piper_link7.STL" />
            </geometry>
            <material name="">
                <color rgba="0.792156862745098 0.819607843137255 0.933333333333333 1" />
            </material>
        </visual>
        <collision>
            <origin xyz="0 0 0" rpy="0 0 0" />
            <geometry>
                <mesh filename="package://piper_description/meshes/piper_link7.STL" />
            </geometry>
        </collision>
    </link>
    <joint name="left_joint7" type="prismatic">
        <origin xyz="0 0 0.1358" rpy="1.5708 0 0" />
        <parent link="left_gripper_base" />
        <child link="left_link7" />
        <axis xyz="0 0 1" />
        <limit lower="0" upper="0.035" effort="10" velocity="1" />
    </joint>
    <link name="left_link8">
        <inertial>
            <origin xyz="0.000651231850419722 -0.0491929869131991 0.00972258769184024" rpy="0 0 0" />
            <mass value="0.025" />
            <inertia ixx="0.00007371" ixy="-0.00000113" ixz="0.00000021" iyy="0.00000781" iyz="-0.00001372" izz="0.0000747" />
        </inertial>
        <visual>
            <origin xyz="0 0 0" rpy="0 0 0" />
            <geometry>
                <mesh filename="package://piper_description/meshes/piper_link8.STL" />
            </geometry>
            <material name="">
                <color rgba="0.792156862745098 0.819607843137255 0.933333333333333 1" />
            </material>
        </visual>
        <collision>
            <origin xyz="0 0 0" rpy="0 0 0" />
            <geometry>
                <mesh filename="package://piper_description/meshes/piper_link8.STL" />
            </geometry>
        </collision>
    </link>
    <joint name="left_joint8" type="prismatic">
        <origin xyz="0 0 0.1358" rpy="1.5708 0 -3.1416" />
        <parent link="left_gripper_base" />
        <child link="left_link8" />
        <axis xyz="0 0 -1" />
        <limit lower="-0.035" upper="0" effort="10" velocity="1" />
    </joint>
    <!-- piper right -->
    <link name="piper_base_link_right">
        <inertial>
            <origin xyz="-0.00473641164191482 2.56829134630247E-05 0.041451518036016" rpy="0 0 0" />
            <mass value="1.02" />
            <inertia ixx="0.00267433" ixy="-0.00000073" ixz="-0.00017389" iyy="0.00282612" iyz="0.0000004" izz="0.00089624" />
        </inertial>
        <visual>
            <origin xyz="0 0 0" rpy="0 0 0" />
            <geometry>
                <mesh filename="package://piper_description/meshes/piper_base_link.STL" />
            </geometry>
            <material name="">
                <color rgba="0.792156862745098 0.819607843137255 0.933333333333333 1" />
            </material>
        </visual>
        <collision>
            <origin xyz="0 0 0" rpy="0 0 0" />
            <geometry>
                <mesh filename="package://piper_description/meshes/piper_base_link.STL" />
            </geometry>
        </collision>
    </link>
    <joint name="right_piper_fix" type="fixed">
        <parent link="double_arm_upper" />
        <child link="piper_base_link_right" />
        <origin xyz="0.053 -0.255 0.57" rpy="0 0 0" />
    </joint>
    <link name="right_link1">
        <inertial>
            <origin xyz="0.000121504734057468 0.000104632162460536 -0.00438597309559853" rpy="0 0 0" />
            <mass value="0.71" />
            <inertia ixx="0.00048916" ixy="-0.00000036" ixz="-0.00000224" iyy="0.00040472" iyz="-0.00000242" izz="0.00043982" />
        </inertial>
        <visual>
            <origin xyz="0 0 0" rpy="0 0 0" />
            <geometry>
                <mesh filename="package://piper_description/meshes/piper_link1.STL" />
            </geometry>
            <material name="">
                <color rgba="0.792156862745098 0.819607843137255 0.933333333333333 1" />
            </material>
        </visual>
        <collision>
            <origin xyz="0 0 0" rpy="0 0 0" />
            <geometry>
                <mesh filename="package://piper_description/meshes/piper_link1.STL" />
            </geometry>
        </collision>
    </link>
    <joint name="right_joint1" type="revolute">
        <origin xyz="0 0 0.123" rpy="0 0 0" />
        <parent link="piper_base_link_right" />
        <child link="right_link1" />
        <axis xyz="0 0 1" />
        <limit lower="-2.618" upper="2.168" effort="100" velocity="5" />
    </joint>
    <link name="right_link2">
        <inertial>
            <origin xyz="0.198666145229743 -0.010926924140076 0.00142121714502687" rpy="0 0 0" />
            <mass value="1.17" />
            <inertia ixx="0.00116918" ixy="-0.00180037" ixz="0.00025146" iyy="0.06785384" iyz="-0.00000455" izz="0.06774489" />
        </inertial>
        <visual>
            <origin xyz="0 0 0" rpy="0 0 0" />
            <geometry>
                <mesh filename="package://piper_description/meshes/piper_link2.STL" />
            </geometry>
            <material name="">
                <color rgba="0.792156862745098 0.819607843137255 0.933333333333333 1" />
            </material>
        </visual>
        <collision>
            <origin xyz="0 0 0" rpy="0 0 0" />
            <geometry>
                <mesh filename="package://piper_description/meshes/piper_link2.STL" />
            </geometry>
        </collision>
    </link>
    <joint name="right_joint2" type="revolute">
        <origin xyz="0 0 0" rpy="1.5708 -0.10095 -3.1416" />
        <parent link="right_link1" />
        <child link="right_link2" />
        <axis xyz="0 0 1" />
        <limit lower="0" upper="3.14" effort="100" velocity="5" />
    </joint>
    <link name="right_link3">
        <inertial>
            <origin xyz="-0.0202737662122021 -0.133914995944595 -0.000458682652737356" rpy="0 0 0" />
            <mass value="0.5" />
            <inertia ixx="0.01361711" ixy="0.00165794" ixz="-0.00000048" iyy="0.00045024" iyz="-0.00000045" izz="0.01380322" />
        </inertial>
        <visual>
            <origin xyz="0 0 0" rpy="0 0 0" />
            <geometry>
                <mesh filename="package://piper_description/meshes/piper_link3.STL" />
            </geometry>
            <material name="">
                <color rgba="0.792156862745098 0.819607843137255 0.933333333333333 1" />
            </material>
        </visual>
        <collision>
            <origin xyz="0 0 0" rpy="0 0 0" />
            <geometry>
                <mesh filename="package://piper_description/meshes/piper_link3.STL" />
            </geometry>
        </collision>
    </link>
    <joint name="right_joint3" type="revolute">
        <origin xyz="0.28503 0 0" rpy="0 0 -1.759" />
        <parent link="right_link2" />
        <child link="right_link3" />
        <axis xyz="0 0 1" />
        <limit lower="-2.967" upper="0" effort="100" velocity="5" />
    </joint>
    <link name="right_link4">
        <inertial>
            <origin xyz="-9.66635791618542E-05 0.000876064475651083 -0.00496880904640868" rpy="0 0 0" />
            <mass value="0.38" />
            <inertia ixx="0.00018501" ixy="0.00000054" ixz="0.00000120" iyy="0.00018965" iyz="-0.00000841" izz="0.00015484" />
        </inertial>
        <visual>
            <origin xyz="0 0 0" rpy="0 0 0" />
            <geometry>
                <mesh filename="package://piper_description/meshes/piper_link4.STL" />
            </geometry>
            <material name="">
                <color rgba="0.792156862745098 0.819607843137255 0.933333333333333 1" />
            </material>
        </visual>
        <collision>
            <origin xyz="0 0 0" rpy="0 0 0" />
            <geometry>
                <mesh filename="package://piper_description/meshes/piper_link4.STL" />
            </geometry>
        </collision>
    </link>
    <joint name="right_joint4" type="revolute">
        <origin xyz="-0.021984 -0.25075 0" rpy="1.5708 0 0" />
        <parent link="right_link3" />
        <child link="right_link4" />
        <axis xyz="0 0 1" />
        <limit lower="-1.745" upper="1.745" effort="100" velocity="5" />
    </joint>
    <link name="right_link5">
        <inertial>
            <origin xyz="-4.10554118924211E-05 -0.0566486692356075 -0.0037205791677906" rpy="0 0 0" />
            <mass value="0.383" />
            <inertia ixx="0.00166169" ixy="0.00000006" ixz="-0.00000007" iyy="0.00018510" iyz="0.00001026" izz="0.00164321" />
        </inertial>
        <visual>
            <origin xyz="0 0 0" rpy="0 0 0" />
            <geometry>
                <mesh filename="package://piper_description/meshes/piper_link5.STL" />
            </geometry>
            <material name="">
                <color rgba="0.792156862745098 0.819607843137255 0.933333333333333 1" />
            </material>
        </visual>
        <collision>
            <origin xyz="0 0 0" rpy="0 0 0" />
            <geometry>
                <mesh filename="package://piper_description/meshes/piper_link5.STL" />
            </geometry>
        </collision>
    </link>
    <joint name="right_joint5" type="revolute">
        <origin xyz="0 0 0" rpy="-1.5708 0 0" />
        <parent link="right_link4" />
        <child link="right_link5" />
        <axis xyz="0 0 1" />
        <limit lower="-1.22" upper="1.22" effort="100" velocity="5" />
    </joint>
    <link name="right_link6">
        <inertial>
            <origin xyz="-8.82590762930069E-05 9.0598378529832E-06 -0.002" rpy="0 0 0" />
            <mass value="0.00699089613564366" />
            <inertia ixx="5.73015540542155E-07" ixy="-1.98305403089247E-22" ixz="-7.2791893904596E-23" iyy="5.73015540542155E-07" iyz="-3.4146026640245E-24" izz="1.06738869138926E-06" />
        </inertial>
        <visual>
            <origin xyz="0 0 0" rpy="0 0 0" />
            <geometry>
                <mesh filename="package://piper_description/meshes/piper_link6.STL" />
            </geometry>
            <material name="">
                <color rgba="0.898039215686275 0.917647058823529 0.929411764705882 1" />
            </material>
        </visual>
        <collision>
            <origin xyz="0 0 0" rpy="0 0 0" />
            <geometry>
                <mesh filename="package://piper_description/meshes/piper_link6.STL" />
            </geometry>
        </collision>
    </link>
    <joint name="right_joint6" type="revolute">
        <origin xyz="8.8259E-05 -0.091 0" rpy="1.5708 0 0" />
        <parent link="right_link5" />
        <child link="right_link6" />
        <axis xyz="0 0 1" />
        <limit lower="-2.0944" upper="2.0944" effort="100" velocity="3" />
    </joint>
    <link name="right_gripper_base">
        <inertial>
            <origin xyz="-0.000183807162235591 8.05033155577911E-05 0.0321436689908876" rpy="0 0 0" />
            <mass value="0.45" />
            <inertia ixx="0.00092934" ixy="0.00000034" ixz="-0.00000738" iyy="0.00071447" iyz="0.00000005" izz="0.00039442" />
        </inertial>
        <visual>
            <origin xyz="0 0 0" rpy="0 0 0" />
            <geometry>
                <mesh filename="package://piper_description/meshes/gripper_base.STL" />
            </geometry>
            <material name="">
                <color rgba="0.792156862745098 0.819607843137255 0.933333333333333 1" />
            </material>
        </visual>
        <collision>
            <origin xyz="0 0 0" rpy="0 0 0" />
            <geometry>
                <mesh filename="package://piper_description/meshes/gripper_base.STL" />
            </geometry>
        </collision>
    </link>
    <joint name="right_joint6_to_gripper_base" type="fixed">
        <origin xyz="0 0 0" rpy="0 0 0" />
        <parent link="right_link6" />
        <child link="right_gripper_base" />
    </joint>
    <link name="right_link7">
        <inertial>
            <origin xyz="0.00065123185041968 -0.0491929869131989 0.00972258769184025" rpy="0 0 0" />
            <mass value="0.025" />
            <inertia ixx="0.00007371" ixy="-0.00000113" ixz="0.00000021" iyy="0.00000781" iyz="-0.00001372" izz="0.0000747" />
        </inertial>
        <visual>
            <origin xyz="0 0 0" rpy="0 0 0" />
            <geometry>
                <mesh filename="package://piper_description/meshes/piper_link7.STL" />
            </geometry>
            <material name="">
                <color rgba="0.792156862745098 0.819607843137255 0.933333333333333 1" />
            </material>
        </visual>
        <collision>
            <origin xyz="0 0 0" rpy="0 0 0" />
            <geometry>
                <mesh filename="package://piper_description/meshes/piper_link7.STL" />
            </geometry>
        </collision>
    </link>
    <joint name="right_joint7" type="prismatic">
        <origin xyz="0 0 0.1358" rpy="1.5708 0 0" />
        <parent link="right_gripper_base" />
        <child link="right_link7" />
        <axis xyz="0 0 1" />
        <limit lower="0" upper="0.035" effort="10" velocity="1" />
    </joint>
    <link name="right_link8">
        <inertial>
            <origin xyz="0.000651231850419722 -0.0491929869131991 0.00972258769184024" rpy="0 0 0" />
            <mass value="0.025" />
            <inertia ixx="0.00007371" ixy="-0.00000113" ixz="0.00000021" iyy="0.00000781" iyz="-0.00001372" izz="0.0000747" />
        </inertial>
        <visual>
            <origin xyz="0 0 0" rpy="0 0 0" />
            <geometry>
                <mesh filename="package://piper_description/meshes/piper_link8.STL" />
            </geometry>
            <material name="">
                <color rgba="0.792156862745098 0.819607843137255 0.933333333333333 1" />
            </material>
        </visual>
        <collision>
            <origin xyz="0 0 0" rpy="0 0 0" />
            <geometry>
                <mesh filename="package://piper_description/meshes/piper_link8.STL" />
            </geometry>
        </collision>
    </link>
    <joint name="right_joint8" type="prismatic">
        <origin xyz="0 0 0.1358" rpy="1.5708 0 -3.1416" />
        <parent link="right_gripper_base" />
        <child link="right_link8" />
        <axis xyz="0 0 -1" />
        <limit lower="-0.035" upper="0" effort="10" velocity="1" />
    </joint>
    <transmission name="trans_joint_wheel_front_right">
        <type>transmission_interface/SimpleTransmission</type>
        <joint name="joint_wheel_front_right">
            <hardwareInterface>hardware_interface/EffortJointInterface</hardwareInterface>
        </joint>
        <actuator name="joint_wheel_front_right_motor">
            <hardwareInterface>hardware_interface/EffortJointInterface</hardwareInterface>
            <mechanicalReduction>1</mechanicalReduction>
        </actuator>
    </transmission>
    <transmission name="trans_joint_wheel_front_left">
        <type>transmission_interface/SimpleTransmission</type>
        <joint name="joint_wheel_front_left">
            <hardwareInterface>hardware_interface/EffortJointInterface</hardwareInterface>
        </joint>
        <actuator name="joint_wheel_front_left_motor">
            <hardwareInterface>hardware_interface/EffortJointInterface</hardwareInterface>
            <mechanicalReduction>1</mechanicalReduction>
        </actuator>
    </transmission>
    <transmission name="trans_joint_wheel_rear_left">
        <type>transmission_interface/SimpleTransmission</type>
        <joint name="joint_wheel_rear_left">
            <hardwareInterface>hardware_interface/EffortJointInterface</hardwareInterface>
        </joint>
        <actuator name="joint_wheel_rear_left_motor">
            <hardwareInterface>hardware_interface/EffortJointInterface</hardwareInterface>
            <mechanicalReduction>1</mechanicalReduction>
        </actuator>
    </transmission>
    <transmission name="trans_joint_wheel_rear_right">
        <type>transmission_interface/SimpleTransmission</type>
        <joint name="joint_wheel_rear_right">
            <hardwareInterface>hardware_interface/EffortJointInterface</hardwareInterface>
        </joint>
        <actuator name="joint_wheel_rear_right_motor">
            <hardwareInterface>hardware_interface/EffortJointInterface</hardwareInterface>
            <mechanicalReduction>1</mechanicalReduction>
        </actuator>
    </transmission>
    <transmission name="trans_left_joint1">
        <type>transmission_interface/SimpleTransmission</type>
        <joint name="left_joint1">
            <hardwareInterface>hardware_interface/EffortJointInterface</hardwareInterface>
        </joint>
        <actuator name="left_joint1_motor">
            <hardwareInterface>hardware_interface/EffortJointInterface</hardwareInterface>
            <mechanicalReduction>1</mechanicalReduction>
        </actuator>
    </transmission>
    <transmission name="trans_left_joint2">
        <type>transmission_interface/SimpleTransmission</type>
        <joint name="left_joint2">
            <hardwareInterface>hardware_interface/EffortJointInterface</hardwareInterface>
        </joint>
        <actuator name="left_joint2_motor">
            <hardwareInterface>hardware_interface/EffortJointInterface</hardwareInterface>
            <mechanicalReduction>1</mechanicalReduction>
        </actuator>
    </transmission>
    <transmission name="trans_left_joint3">
        <type>transmission_interface/SimpleTransmission</type>
        <joint name="left_joint3">
            <hardwareInterface>hardware_interface/EffortJointInterface</hardwareInterface>
        </joint>
        <actuator name="left_joint3_motor">
            <hardwareInterface>hardware_interface/EffortJointInterface</hardwareInterface>
            <mechanicalReduction>1</mechanicalReduction>
        </actuator>
    </transmission>
    <transmission name="trans_left_joint4">
        <type>transmission_interface/SimpleTransmission</type>
        <joint name="left_joint4">
            <hardwareInterface>hardware_interface/EffortJointInterface</hardwareInterface>
        </joint>
        <actuator name="left_joint4_motor">
            <hardwareInterface>hardware_interface/EffortJointInterface</hardwareInterface>
            <mechanicalReduction>1</mechanicalReduction>
        </actuator>
    </transmission>
    <transmission name="trans_left_joint5">
        <type>transmission_interface/SimpleTransmission</type>
        <joint name="left_joint5">
            <hardwareInterface>hardware_interface/EffortJointInterface</hardwareInterface>
        </joint>
        <actuator name="left_joint5_motor">
            <hardwareInterface>hardware_interface/EffortJointInterface</hardwareInterface>
            <mechanicalReduction>1</mechanicalReduction>
        </actuator>
    </transmission>
    <transmission name="trans_left_joint6">
        <type>transmission_interface/SimpleTransmission</type>
        <joint name="left_joint6">
            <hardwareInterface>hardware_interface/EffortJointInterface</hardwareInterface>
        </joint>
        <actuator name="left_joint6_motor">
            <hardwareInterface>hardware_interface/EffortJointInterface</hardwareInterface>
            <mechanicalReduction>1</mechanicalReduction>
        </actuator>
    </transmission>
    <transmission name="trans_left_joint7">
        <type>transmission_interface/SimpleTransmission</type>
        <joint name="left_joint7">
            <hardwareInterface>hardware_interface/EffortJointInterface</hardwareInterface>
        </joint>
        <actuator name="left_joint7_motor">
            <hardwareInterface>hardware_interface/EffortJointInterface</hardwareInterface>
            <mechanicalReduction>1</mechanicalReduction>
        </actuator>
    </transmission>
    <transmission name="trans_left_joint8">
        <type>transmission_interface/SimpleTransmission</type>
        <joint name="left_joint8">
            <hardwareInterface>hardware_interface/EffortJointInterface</hardwareInterface>
        </joint>
        <actuator name="left_joint8_motor">
            <hardwareInterface>hardware_interface/EffortJointInterface</hardwareInterface>
            <mechanicalReduction>1</mechanicalReduction>
        </actuator>
    </transmission>
    <transmission name="trans_right_joint1">
        <type>transmission_interface/SimpleTransmission</type>
        <joint name="right_joint1">
            <hardwareInterface>hardware_interface/EffortJointInterface</hardwareInterface>
        </joint>
        <actuator name="right_joint1_motor">
            <hardwareInterface>hardware_interface/EffortJointInterface</hardwareInterface>
            <mechanicalReduction>1</mechanicalReduction>
        </actuator>
    </transmission>
    <transmission name="trans_right_joint2">
        <type>transmission_interface/SimpleTransmission</type>
        <joint name="right_joint2">
            <hardwareInterface>hardware_interface/EffortJointInterface</hardwareInterface>
        </joint>
        <actuator name="right_joint2_motor">
            <hardwareInterface>hardware_interface/EffortJointInterface</hardwareInterface>
            <mechanicalReduction>1</mechanicalReduction>
        </actuator>
    </transmission>
    <transmission name="trans_right_joint3">
        <type>transmission_interface/SimpleTransmission</type>
        <joint name="right_joint3">
            <hardwareInterface>hardware_interface/EffortJointInterface</hardwareInterface>
        </joint>
        <actuator name="right_joint3_motor">
            <hardwareInterface>hardware_interface/EffortJointInterface</hardwareInterface>
            <mechanicalReduction>1</mechanicalReduction>
        </actuator>
    </transmission>
    <transmission name="trans_right_joint4">
        <type>transmission_interface/SimpleTransmission</type>
        <joint name="right_joint4">
            <hardwareInterface>hardware_interface/EffortJointInterface</hardwareInterface>
        </joint>
        <actuator name="right_joint4_motor">
            <hardwareInterface>hardware_interface/EffortJointInterface</hardwareInterface>
            <mechanicalReduction>1</mechanicalReduction>
        </actuator>
    </transmission>
    <transmission name="trans_right_joint5">
        <type>transmission_interface/SimpleTransmission</type>
        <joint name="right_joint5">
            <hardwareInterface>hardware_interface/EffortJointInterface</hardwareInterface>
        </joint>
        <actuator name="right_joint5_motor">
            <hardwareInterface>hardware_interface/EffortJointInterface</hardwareInterface>
            <mechanicalReduction>1</mechanicalReduction>
        </actuator>
    </transmission>
    <transmission name="trans_right_joint6">
        <type>transmission_interface/SimpleTransmission</type>
        <joint name="right_joint6">
            <hardwareInterface>hardware_interface/EffortJointInterface</hardwareInterface>
        </joint>
        <actuator name="right_joint6_motor">
            <hardwareInterface>hardware_interface/EffortJointInterface</hardwareInterface>
            <mechanicalReduction>1</mechanicalReduction>
        </actuator>
    </transmission>
    <transmission name="trans_right_joint7">
        <type>transmission_interface/SimpleTransmission</type>
        <joint name="right_joint7">
            <hardwareInterface>hardware_interface/EffortJointInterface</hardwareInterface>
        </joint>
        <actuator name="right_joint7_motor">
            <hardwareInterface>hardware_interface/EffortJointInterface</hardwareInterface>
            <mechanicalReduction>1</mechanicalReduction>
        </actuator>
    </transmission>
    <transmission name="trans_right_joint8">
        <type>transmission_interface/SimpleTransmission</type>
        <joint name="right_joint8">
            <hardwareInterface>hardware_interface/EffortJointInterface</hardwareInterface>
        </joint>
        <actuator name="right_joint8_motor">
            <hardwareInterface>hardware_interface/EffortJointInterface</hardwareInterface>
            <mechanicalReduction>1</mechanicalReduction>
        </actuator>
    </transmission>
    <gazebo>
        <plugin name="gazebo_ros_control" filename="libgazebo_ros_control.so">
            <robotNamespace>/</robotNamespace>
        </plugin>
    </gazebo>
</robot>

