<?xml version="1.0" encoding="utf-8" ?>
<!-- This URDF was automatically created by SolidWorks to URDF Exporter! Originally created by Stephen Brawner (brawner@gmail.com) 
     Commit Version: 1.6.0-4-g7f85cfe  Build Version: 1.6.7995.38578
     For more information, please see http://wiki.ros.org/sw_urdf_exporter -->
<robot name="arm12">
    <link name="rotated_base" />
    <joint name="rot_to_base" type="fixed">
        <parent link="rotated_base" />
        <child link="base_link" />
        <origin xyz="0 0 0" rpy="0 3.14 0" />
    </joint>
    <link name="base_link">
        <inertial>
            <origin xyz="-0.114741653388133 -0.00394836028883594 -0.0536105920933669" rpy="0 0 0" />
            <mass value="2.63443753992699" />
            <inertia ixx="0.00189567328668365" ixy="7.29873865389891E-06" ixz="0.000140090900098037" iyy="0.158992383742472" iyz="1.36209227842431E-06" izz="0.158257846821755" />
        </inertial>
        <visual>
            <origin xyz="0 0 0" rpy="0 0 0" />
            <geometry>
                <mesh filename="package://arm12/meshes/base_link.STL" />
            </geometry>
            <material name="">
                <color rgba="0.792156862745098 0.819607843137255 0.933333333333333 1" />
            </material>
        </visual>
        <collision>
            <origin xyz="0 0 0" rpy="0 0 0" />
            <geometry>
                <mesh filename="package://arm12/meshes/base_link.STL" />
            </geometry>
        </collision>
    </link>
    <link name="l1">
        <inertial>
            <origin xyz="0.403597483420043 -0.0414638574022828 0.00700359932104074" rpy="0 0 0" />
            <mass value="0.381600228345592" />
            <inertia ixx="0.000152419359459052" ixy="-1.16717541525886E-07" ixz="-4.78639401455686E-07" iyy="0.00015874224871389" iyz="3.26007402233397E-07" izz="0.000167838112577603" />
        </inertial>
        <visual>
            <origin xyz="0 0 0" rpy="0 0 0" />
            <geometry>
                <mesh filename="package://arm12/meshes/l1.STL" />
            </geometry>
            <material name="">
                <color rgba="0.898039215686275 0.917647058823529 0.929411764705882 1" />
            </material>
        </visual>
        <collision>
            <origin xyz="0 0 0" rpy="0 0 0" />
            <geometry>
                <mesh filename="package://arm12/meshes/l1.STL" />
            </geometry>
        </collision>
    </link>
    <joint name="j1" type="prismatic">
        <origin xyz="-0.79073 0.0075 -0.026676" rpy="1.5708 0 0" />
        <parent link="base_link" />
        <child link="l1" />
        <axis xyz="1 0.00024256 0" />
        <limit lower="-1" upper="1" effort="1000" velocity="1000" />
    </joint>
    <link name="l11">
        <inertial>
            <origin xyz="0.109124708134365 -0.106742142823085 0.0291269836365173" rpy="0 0 0" />
            <mass value="0.308192429361636" />
            <inertia ixx="0.00036660835632017" ixy="0.000236532188858594" ixz="-5.91891737788076E-05" iyy="0.000377052003364126" iyz="5.79126892712075E-05" izz="0.000595833629485193" />
        </inertial>
        <visual>
            <origin xyz="0 0 0" rpy="0 0 0" />
            <geometry>
                <mesh filename="package://arm12/meshes/l11.STL" />
            </geometry>
            <material name="">
                <color rgba="0.792156862745098 0.819607843137255 0.933333333333333 1" />
            </material>
        </visual>
        <collision>
            <origin xyz="0 0 0" rpy="0 0 0" />
            <geometry>
                <mesh filename="package://arm12/meshes/l11.STL" />
            </geometry>
        </collision>
    </link>
    <joint name="j11" type="continuous">
        <origin xyz="0.403574468337888 -0.0486058728976355 -0.000248553231492891" rpy="0 0 0" />
        <parent link="l1" />
        <child link="l11" />
        <axis xyz="0 0 -1" />
    </joint>
    <link name="l2">
        <inertial>
            <origin xyz="1.0157003601035 -0.0384463563381593 0.00765610841163893" rpy="0 0 0" />
            <mass value="0.51688405008029" />
            <inertia ixx="0.000289252991255811" ixy="6.16500231917276E-07" ixz="-1.38368241480024E-06" iyy="0.000291829291446418" iyz="-1.10552388292668E-06" izz="0.00026788505040365" />
        </inertial>
        <visual>
            <origin xyz="0 0 0" rpy="0 0 0" />
            <geometry>
                <mesh filename="package://arm12/meshes/l2.STL" />
            </geometry>
            <material name="">
                <color rgba="0.898039215686275 0.917647058823529 0.929411764705882 1" />
            </material>
        </visual>
        <collision>
            <origin xyz="0 0 0" rpy="0 0 0" />
            <geometry>
                <mesh filename="package://arm12/meshes/l2.STL" />
            </geometry>
        </collision>
    </link>
    <joint name="j2" type="prismatic">
        <origin xyz="-0.79073 0.0075 -0.026676" rpy="1.5708 0 0" />
        <parent link="base_link" />
        <child link="l2" />
        <axis xyz="1 0.00024256 0" />
        <limit lower="-1" upper="1" effort="1000" velocity="1000" />
    </joint>
    <link name="l3">
        <inertial>
            <origin xyz="-0.10814121670337 -0.105773126393835 0.0288760940795127" rpy="0 0 0" />
            <mass value="0.306128922940993" />
            <inertia ixx="0.000367090541907876" ixy="-0.000237220677320172" ixz="5.90721357269542E-05" iyy="0.000377593275938236" iyz="5.77716342409563E-05" izz="0.000596928132744383" />
        </inertial>
        <visual>
            <origin xyz="0 0 0" rpy="0 0 0" />
            <geometry>
                <mesh filename="package://arm12/meshes/l3.STL" />
            </geometry>
            <material name="">
                <color rgba="0.792156862745098 0.819607843137255 0.933333333333333 1" />
            </material>
        </visual>
        <collision>
            <origin xyz="0 0 0" rpy="0 0 0" />
            <geometry>
                <mesh filename="package://arm12/meshes/l3.STL" />
            </geometry>
        </collision>
    </link>
    <joint name="j3" type="continuous">
        <origin xyz="1.0158 -0.048606 -0.00024711" rpy="0 0 0" />
        <parent link="l2" />
        <child link="l3" />
        <axis xyz="0 0 -1" />
        <limit lower="1000" upper="1000" effort="1000" velocity="1000" />
    </joint>
    <link name="l4">
        <inertial>
            <origin xyz="-0.0247644704780808 -0.0233597492007901 0.033905617015353" rpy="0 0 0" />
            <mass value="0.247877954974344" />
            <inertia ixx="0.000275512262276771" ixy="-4.01235172214852E-08" ixz="5.68470398676511E-07" iyy="0.000303231827207215" iyz="4.68448608364464E-05" izz="0.000495903390975614" />
        </inertial>
        <visual>
            <origin xyz="0 0 0" rpy="0 0 0" />
            <geometry>
                <mesh filename="package://arm12/meshes/l4.STL" />
            </geometry>
            <material name="">
                <color rgba="1 1 1 1" />
            </material>
        </visual>
        <collision>
            <origin xyz="0 0 0" rpy="0 0 0" />
            <geometry>
                <mesh filename="package://arm12/meshes/l4.STL" />
            </geometry>
        </collision>
    </link>
    <joint name="j4" type="continuous">
        <origin xyz="-0.2814 -0.27508 0.049459" rpy="0 0 0" />
        <parent link="l3" />
        <child link="l4" />
        <axis xyz="0 0 1" />
        <limit lower="1000" upper="1000" effort="1000" velocity="1000" />
    </joint>
    <link name="l6">
        <inertial>
            <origin xyz="0.0835083121801821 -0.0131318490598266 -0.022315022598535" rpy="0 0 0" />
            <mass value="0.492993890644909" />
            <inertia ixx="0.000390471608455916" ixy="2.48268434817755E-06" ixz="0.000302295718302552" iyy="0.00155512945705818" iyz="-1.20122073303538E-06" izz="0.00147705952278512" />
        </inertial>
        <visual>
            <origin xyz="0 0 0" rpy="0 0 0" />
            <geometry>
                <mesh filename="package://arm12/meshes/l6.STL" />
            </geometry>
            <material name="">
                <color rgba="1 1 1 1" />
            </material>
        </visual>
        <collision>
            <origin xyz="0 0 0" rpy="0 0 0" />
            <geometry>
                <mesh filename="package://arm12/meshes/l6.STL" />
            </geometry>
        </collision>
    </link>
    <joint name="j6" type="continuous">
        <origin xyz="-0.031134 -0.097956 0.059414" rpy="0 0 0" />
        <parent link="l4" />
        <child link="l6" />
        <axis xyz="0 1 0" />
        <limit lower="1000" upper="1000" effort="1000" velocity="1000" />
    </joint>
    <link name="l7">
        <inertial>
            <origin xyz="0.0315318501806746 0.00583507478957768 -0.0817967507514115" rpy="0 0 0" />
            <mass value="0.200740625287396" />
            <inertia ixx="0.000563180696639149" ixy="8.48547014814516E-05" ixz="0.000202999903698582" iyy="0.000610313185565538" iyz="-0.000156946216691284" izz="0.000315973335029523" />
        </inertial>
        <visual>
            <origin xyz="0 0 0" rpy="0 0 0" />
            <geometry>
                <mesh filename="package://arm12/meshes/l7.STL" />
            </geometry>
            <material name="">
                <color rgba="0.792156862745098 0.819607843137255 0.933333333333333 1" />
            </material>
        </visual>
        <collision>
            <origin xyz="0 0 0" rpy="0 0 0" />
            <geometry>
                <mesh filename="package://arm12/meshes/l7.STL" />
            </geometry>
        </collision>
    </link>
    <joint name="j7" type="continuous">
        <origin xyz="0.16802 0 -0.043732" rpy="0 0 0" />
        <parent link="l6" />
        <child link="l7" />
        <axis xyz="0 1 0" />
        <limit lower="1000" upper="1000" effort="1000" velocity="1000" />
    </joint>
    <link name="l8">
        <inertial>
            <origin xyz="-0.00639785855543679 -0.105467190035519 0.0332454721635889" rpy="0 0 0" />
            <mass value="0.232745208884819" />
            <inertia ixx="0.000344329566709667" ixy="-0.000100351533357395" ixz="-3.41790292256826E-06" iyy="0.000220748774570507" iyz="9.99580236012298E-06" izz="0.000406188026813068" />
        </inertial>
        <visual>
            <origin xyz="0 0 0" rpy="0 0 0" />
            <geometry>
                <mesh filename="package://arm12/meshes/l8.STL" />
            </geometry>
            <material name="">
                <color rgba="1 1 1 1" />
            </material>
        </visual>
        <collision>
            <origin xyz="0 0 0" rpy="0 0 0" />
            <geometry>
                <mesh filename="package://arm12/meshes/l8.STL" />
            </geometry>
        </collision>
    </link>
    <joint name="j8" type="continuous">
        <origin xyz="0.057439 -0.0094087 -0.13328" rpy="0 0 0" />
        <parent link="l7" />
        <child link="l8" />
        <axis xyz="-0.90237 0 -0.43096" />
        <limit lower="1000" upper="1000" effort="1000" velocity="1000" />
    </joint>
    <!--  在 l8 后面挂一个 tool0 -->
    <link name="tool0">
        <!-- 如果你想在 RViz 里可视化，可以加一个小盒子或球体；不想可视化也可以留空 -->
        <visual>
            <origin xyz="0 0 0" rpy="0 0 0" />
            <geometry>
                <sphere radius="0.01" />
            </geometry>
            <material name="Grey">
                <color rgba="1 0.5 0.5 1" />
            </material>
        </visual>
        <collision>
            <origin xyz="0 0 0" rpy="0 0 0" />
            <geometry>
                <sphere radius="0.001" />
            </geometry>
        </collision>
        <!-- 惯量随便给一个很小的，或者干脆不加 inertial 也行 -->
        <inertial>
            <mass value="0.1" />
            <origin xyz="0 0 0" rpy="0 0 0" />
            <inertia ixx="0.03" iyy="0.03" izz="0.03" ixy="0.0" ixz="0.0" iyz="0.0" />
        </inertial>
    </link>
    <joint name="tool0_fixed_joint" type="fixed">
        <parent link="l8" />
        <child link="tool0" />
        <!-- 如果你的夹爪前端需要在 l8 的某个偏移位置，就在这里改 xyz -->
        <origin xyz="-0.03 -0.2 0.05" rpy="0 0 0" />
    </joint>
    <transmission name="trans_j1">
        <type>transmission_interface/SimpleTransmission</type>
        <joint name="j1">
            <hardwareInterface>hardware_interface/EffortJointInterface</hardwareInterface>
        </joint>
        <actuator name="j1_motor">
            <hardwareInterface>hardware_interface/EffortJointInterface</hardwareInterface>
            <mechanicalReduction>1</mechanicalReduction>
        </actuator>
    </transmission>
    <transmission name="trans_j11">
        <type>transmission_interface/SimpleTransmission</type>
        <joint name="j11">
            <hardwareInterface>hardware_interface/EffortJointInterface</hardwareInterface>
        </joint>
        <actuator name="j11_motor">
            <hardwareInterface>hardware_interface/EffortJointInterface</hardwareInterface>
            <mechanicalReduction>1</mechanicalReduction>
        </actuator>
    </transmission>
    <transmission name="trans_j2">
        <type>transmission_interface/SimpleTransmission</type>
        <joint name="j2">
            <hardwareInterface>hardware_interface/EffortJointInterface</hardwareInterface>
        </joint>
        <actuator name="j2_motor">
            <hardwareInterface>hardware_interface/EffortJointInterface</hardwareInterface>
            <mechanicalReduction>1</mechanicalReduction>
        </actuator>
    </transmission>
    <transmission name="trans_j3">
        <type>transmission_interface/SimpleTransmission</type>
        <joint name="j3">
            <hardwareInterface>hardware_interface/EffortJointInterface</hardwareInterface>
        </joint>
        <actuator name="j3_motor">
            <hardwareInterface>hardware_interface/EffortJointInterface</hardwareInterface>
            <mechanicalReduction>1</mechanicalReduction>
        </actuator>
    </transmission>
    <transmission name="trans_j4">
        <type>transmission_interface/SimpleTransmission</type>
        <joint name="j4">
            <hardwareInterface>hardware_interface/EffortJointInterface</hardwareInterface>
        </joint>
        <actuator name="j4_motor">
            <hardwareInterface>hardware_interface/EffortJointInterface</hardwareInterface>
            <mechanicalReduction>1</mechanicalReduction>
        </actuator>
    </transmission>
    <transmission name="trans_j6">
        <type>transmission_interface/SimpleTransmission</type>
        <joint name="j6">
            <hardwareInterface>hardware_interface/EffortJointInterface</hardwareInterface>
        </joint>
        <actuator name="j6_motor">
            <hardwareInterface>hardware_interface/EffortJointInterface</hardwareInterface>
            <mechanicalReduction>1</mechanicalReduction>
        </actuator>
    </transmission>
    <transmission name="trans_j7">
        <type>transmission_interface/SimpleTransmission</type>
        <joint name="j7">
            <hardwareInterface>hardware_interface/EffortJointInterface</hardwareInterface>
        </joint>
        <actuator name="j7_motor">
            <hardwareInterface>hardware_interface/EffortJointInterface</hardwareInterface>
            <mechanicalReduction>1</mechanicalReduction>
        </actuator>
    </transmission>
    <transmission name="trans_j8">
        <type>transmission_interface/SimpleTransmission</type>
        <joint name="j8">
            <hardwareInterface>hardware_interface/EffortJointInterface</hardwareInterface>
        </joint>
        <actuator name="j8_motor">
            <hardwareInterface>hardware_interface/EffortJointInterface</hardwareInterface>
            <mechanicalReduction>1</mechanicalReduction>
        </actuator>
    </transmission>
    <gazebo>
        <plugin name="gazebo_ros_control" filename="libgazebo_ros_control.so">
            <robotNamespace>/</robotNamespace>
        </plugin>
    </gazebo>
</robot>

